Workbook

Sheet Budget vs Actual - Yearly
A1: Budget Line Item | B1: Yearly Budget ($) | C1: Actual Spent ($) | D1: Remaining ($) | E1: % Used | F1: Notes
A2: Admin | B2: =sum(B3:B4) -> 700 | C2: =sum(C3:C4) -> 203 | D2: =B2-C2 -> 497 | E2: =iferror(C2/B2, 0) -> 0.29
A3: Tech | B3: ='Budget vs Actual - Monthly'!X4 -> 420 | C3: ='Budget vs Actual - Monthly'!Y4 -> 203 | D3: =B3-C3 -> 217 | E3: =iferror(C3/B3, 0) -> 0.48333333
A4: Other Funds | B4: ='Budget vs Actual - Monthly'!X5 -> 280 | C4: ='Budget vs Actual - Monthly'!Y5 -> 0 | D4: =B4-C4 -> 280 | E4: =iferror(C4/B4, 0) -> 0
A5: Workshops/Education | B5: =SUM(B6:B7) -> 4800 | C5: =SUM(C6:C7) -> 3091.17 | D5: =B5-C5 -> 1708.83 | E5: =iferror(C5/B5, 0) -> 0.64399375
A6: Guest Speaker | B6: ='Budget vs Actual - Monthly'!X7 -> 4000 | C6: ='Budget vs Actual - Monthly'!Y7 -> 3131.17 | D6: =B6-C6 -> 868.83 | E6: =iferror(C6/B6, 0) -> 0.7827925
A7: Toastmasters | B7: ='Budget vs Actual - Monthly'!X8 -> 800 | C7: ='Budget vs Actual - Monthly'!Y8 -> -40 | D7: =B7-C7 -> 840 | E7: =iferror(C7/B7, 0) -> -0.05
A8: Monthly Masjid Event | B8: =SUM(B9:B10) -> 3600 | C8: =SUM(C9:C10) -> 763.81 | D8: =B8-C8 -> 2836.19 | E8: =iferror(C8/B8, 0) -> 0.21216944
A9: Youth Night | B9: ='Budget vs Actual - Monthly'!X10 -> 1250 | C9: ='Budget vs Actual - Monthly'!Y10 -> 363.81 | D9: =B9-C9 -> 886.19 | E9: =iferror(C9/B9, 0) -> 0.291048
A10: Family Night | B10: ='Budget vs Actual - Monthly'!X11 -> 2350 | C10: ='Budget vs Actual - Monthly'!Y11 -> 400 | D10: =B10-C10 -> 1950 | E10: =iferror(C10/B10, 0) -> 0.17021277
A11: Ramadan | B11: =sum(B12:B17) -> 3300 | C11: =sum(C12:C17) -> 3178.92 | D11: =B11-C11 -> 121.08 | E11: =iferror(C11/B11, 0) -> 0.96330909
A12: Youth Girls Itikaaf | B12: ='Budget vs Actual - Monthly'!X13 -> 0 | C12: ='Budget vs Actual - Monthly'!Y13 -> 100.13 | D12: =B12-C12 -> -100.13 | E12: =iferror(C12/B12, 0) -> 0 | F12: main expenses tracked separately by Faiza Aunty
A13: Youth Boys Itikaaf | B13: ='Budget vs Actual - Monthly'!X14 -> 800 | C13: ='Budget vs Actual - Monthly'!Y14 -> 490.41 | D13: =B13-C13 -> 309.59 | E13: =iferror(C13/B13, 0) -> 0.6130125
A14: Jr. Youth Girls Itikaaf | B14: ='Budget vs Actual - Monthly'!X15 -> 0 | C14: ='Budget vs Actual - Monthly'!Y15 -> 0 | D14: =B14-C14 -> 0 | E14: =iferror(C14/B14, 0) -> 0 | F14: main expenses tracked separately by Faiza Aunty
A15: Jr. Youth Boys Itikaaf | B15: ='Budget vs Actual - Monthly'!X16 -> 500 | C15: ='Budget vs Actual - Monthly'!Y16 -> 424.29 | D15: =B15-C15 -> 75.71 | E15: =iferror(C15/B15, 0) -> 0.84858
A16: Quran Competition | B16: ='Budget vs Actual - Monthly'!X17 -> 1000 | C16: ='Budget vs Actual - Monthly'!Y17 -> 1071.7 | D16: =B16-C16 -> -71.7 | E16: =iferror(C16/B16, 0) -> 1.0717
A17: Youth Eid Festival | B17: ='Budget vs Actual - Monthly'!X18 -> 1000 | C17: ='Budget vs Actual - Monthly'!Y18 -> 1092.39 | D17: =B17-C17 -> -92.39 | E17: =iferror(C17/B17, 0) -> 1.09239
A18: Special Events | B18: =sum(B19,B20) -> 2500 | C18: =sum(C19,C20) -> 3000 | D18: =B18-C18 -> -500 | E18: =iferror(C18/B18, 0) -> 1.2
A19: Family BBQ | B19: ='Budget vs Actual - Monthly'!X20 -> 2500 | C19: ='Budget vs Actual - Monthly'!Y20 -> 0 | D19: =B19-C19 -> 2500 | E19: =iferror(C19/B19, 0) -> 0
A20: Ibn Katheer Quran Competition | B20: ='Budget vs Actual - Monthly'!X21 -> 0 | C20: ='Budget vs Actual - Monthly'!Y21 -> 3000 | D20: =B20-C20 -> -3000 | E20: =iferror(C20/B20, 0) -> 0
A21: TOTALS | B21: =sum(B2,B5,B8,B11,B18) -> 14900 | C21: =sum(C2,C5,C8,C11,C18) -> 10236.9 | D21: =sum(D2,D5,D8,D11,D18) -> 4663.1 | E21: =C21/B21 -> 0.68704027

Sheet Budget vs Actual - Monthly
B1: September | C1: 2025 | D1: October | E1: 2025 | F1: November | G1: 2025 | H1: December | I1: 2025 | J1: January | K1: 2026 | L1: Ramadan | M1: 2026 | N1: April | O1: 2026 | P1: May | Q1: 2026 | R1: Jun | S1: 2026 | T1: Jul | U1: 2026 | V1: Aug | W1: 2026 | X1: Year Totals
A2: Budget Line Item | B2: Budget | C2: Actual | D2: Budget | E2: Actual | F2: Budget | G2: Actual | H2: Budget | I2: Actual | J2: Budget | K2: Actual | L2: Budget | M2: Actual | N2: Budget | O2: Actual | P2: Budget | Q2: Actual | R2: Budget | S2: Actual | T2: Budget | U2: Actual | V2: Budget | W2: Actual | X2: Year Budget | Y2: Year Actual
A3: Admin | B3: =SUM(B4:B5) -> 315 | C3: =SUM(C4:C5) -> 0 | D3: =SUM(D4:D5) -> 35 | E3: =SUM(E4:E5) -> 0 | F3: =SUM(F4:F5) -> 35 | G3: =SUM(G4:G5) -> 0 | H3: =SUM(H4:H5) -> 35 | I3: =SUM(I4:I5) -> 0 | ... W3: =SUM(W4:W5) -> 0 | X3: =sum(X4:X5) -> 700 | Y3: =sum(Y4:Y5) -> 203
A4: Tech | B4: 35 | C4: =sumifs('Expenses Log'!$H:$H,'Expenses Log'!$B:$B, $A4,'Expenses Log'!$M:$M, B$1) -> 0 | D4: 35 | E4: =sumifs('Expenses Log'!$H:$H,'Expenses Log'!$B:$B, $A4,'Expenses Log'!$M:$M, D$1) -> 0 | F4: 35 | G4: =sumifs('Expenses Log'!$H:$H,'Expenses Log'!$B:$B, $A4,'Expenses Log'!$M:$M, F$1) -> 0 | H4: 35 | I4: =sumifs('Expenses Log'!$H:$H,'Expenses Log'!$B:$B, $A4,'Expenses Log'!$M:$M, H$1) -> 0 | J4: 35 | K4: =sumifs('Expenses Log'!$H:$H,'Expenses Log'!$B:$B, $A4,'Expenses Log'!$M:$M, J$1) -> 203 | L4: 70 | M4: =sumifs('Expenses Log'!$H:$H,'Expenses Log'!$B:$B, $A4,'Expenses Log'!$M:$M, L$1) -> 0 | N4: 35 | O4: =sumifs('Expenses Log'!$H:$H,'Expenses Log'!$B:$B, $A4,'Expenses Log'!$M:$M, N$1) -> 0 | P4: 35 | Q4: =sumifs('Expenses Log'!$H:$H,'Expenses Log'!$B:$B, $A4,'Expenses Log'!$M:$M, P$1) -> 0 | R4: 35 | S4: =sumifs('Expenses Log'!$H:$H,'Expenses Log'!$B:$B, $A4,'Expenses Log'!$M:$M, R$1) -> 0 | T4: 35 | U4: =sumifs('Expenses Log'!$H:$H,'Expenses Log'!$B:$B, $A4,'Expenses Log'!$M:$M, T$1) -> 0 | V4: 35 | W4: =sumifs('Expenses Log'!$H:$H,'Expenses Log'!$B:$B, $A4,'Expenses Log'!$M:$M, V$1) -> 0 | X4: =sum(B4,D4,F4,H4,J4,L4,N4,P4,R4,T4,V4) -> 420 | Y4: =sum(C4,E4,G4,I4,K4,M4,O4,Q4,S4,U4,W4) -> 203
A5: Other Funds | B5: 280 | C5: =sumifs('Expenses Log'!$H:$H,'Expenses Log'!$B:$B, $A5,'Expenses Log'!$M:$M, B$1) -> 0 | E5: =sumifs('Expenses Log'!$H:$H,'Expenses Log'!$B:$B, $A5,'Expenses Log'!$M:$M, D$1) -> 0 | G5: =sumifs('Expenses Log'!$H:$H,'Expenses Log'!$B:$B, $A5,'Expenses Log'!$M:$M, F$1) -> 0 | I5: =sumifs('Expenses Log'!$H:$H,'Expenses Log'!$B:$B, $A5,'Expenses Log'!$M:$M, H$1) -> 0 | K5: =sumifs('Expenses Log'!$H:$H,'Expenses Log'!$B:$B, $A5,'Expenses Log'!$M:$M, J$1) -> 0 | M5: =sumifs('Expenses Log'!$H:$H,'Expenses Log'!$B:$B, $A5,'Expenses Log'!$M:$M, L$1) -> 0 | O5: =sumifs('Expenses Log'!$H:$H,'Expenses Log'!$B:$B, $A5,'Expenses Log'!$M:$M, N$1) -> 0 | Q5: =sumifs('Expenses Log'!$H:$H,'Expenses Log'!$B:$B, $A5,'Expenses Log'!$M:$M, P$1) -> 0 | S5: =sumifs('Expenses Log'!$H:$H,'Expenses Log'!$B:$B, $A5,'Expenses Log'!$M:$M, R$1) -> 0 | U5: =sumifs('Expenses Log'!$H:$H,'Expenses Log'!$B:$B, $A5,'Expenses Log'!$M:$M, T$1) -> 0 | W5: =sumifs('Expenses Log'!$H:$H,'Expenses Log'!$B:$B, $A5,'Expenses Log'!$M:$M, V$1) -> 0 | X5: =sum(B5,D5,F5,H5,J5,L5,N5,P5,R5,T5,V5) -> 280 | Y5: =sum(C5,E5,G5,I5,K5,M5,O5,Q5,S5,U5,W5) -> 0
A6: Workshops/Education | B6: =SUM(B7:B8) -> 200 | C6: =SUM(C7:C8) -> 0 | D6: =SUM(D7:D8) -> 0 | E6: =SUM(E7:E8) -> 0 | F6: =SUM(F7:F8) -> 0 | G6: =SUM(G7:G8) -> 0 | H6: =SUM(H7:H8) -> 200 | I6: =SUM(I7:I8) -> 0 | ... Y6: =SUM(Y7:Y8) -> 3091.17
A7: Guest Speaker | C7: =sumifs('Expenses Log'!$H:$H,'Expenses Log'!$B:$B, $A7,'Expenses Log'!$M:$M, B$1) -> 0 | E7: =sumifs('Expenses Log'!$H:$H,'Expenses Log'!$B:$B, $A7,'Expenses Log'!$M:$M, D$1) -> 0 | G7: =sumifs('Expenses Log'!$H:$H,'Expenses Log'!$B:$B, $A7,'Expenses Log'!$M:$M, F$1) -> 0 | I7: =sumifs('Expenses Log'!$H:$H,'Expenses Log'!$B:$B, $A7,'Expenses Log'!$M:$M, H$1) -> 0 | J7: 2000 | K7: =sumifs('Expenses Log'!$H:$H,'Expenses Log'!$B:$B, $A7,'Expenses Log'!$M:$M, J$1) -> 1631.17 | M7: =sumifs('Expenses Log'!$H:$H,'Expenses Log'!$B:$B, $A7,'Expenses Log'!$M:$M, L$1) -> 0 | O7: =sumifs('Expenses Log'!$H:$H,'Expenses Log'!$B:$B, $A7,'Expenses Log'!$M:$M, N$1) -> 750 | P7: 2000 | Q7: =sumifs('Expenses Log'!$H:$H,'Expenses Log'!$B:$B, $A7,'Expenses Log'!$M:$M, P$1) -> 750 | S7: =sumifs('Expenses Log'!$H:$H,'Expenses Log'!$B:$B, $A7,'Expenses Log'!$M:$M, R$1) -> 0 | U7: =sumifs('Expenses Log'!$H:$H,'Expenses Log'!$B:$B, $A7,'Expenses Log'!$M:$M, T$1) -> 0 | W7: =sumifs('Expenses Log'!$H:$H,'Expenses Log'!$B:$B, $A7,'Expenses Log'!$M:$M, V$1) -> 0 | X7: =sum(B7,D7,F7,H7,J7,L7,N7,P7,R7,T7,V7) -> 4000 | Y7: =sum(C7,E7,G7,I7,K7,M7,O7,Q7,S7,U7,W7) -> 3131.17
A8: Toastmasters | B8: 200 | C8: =sumifs('Expenses Log'!$H:$H,'Expenses Log'!$B:$B, $A8,'Expenses Log'!$M:$M, B$1) -> 0 | E8: =sumifs('Expenses Log'!$H:$H,'Expenses Log'!$B:$B, $A8,'Expenses Log'!$M:$M, D$1) -> 0 | G8: =sumifs('Expenses Log'!$H:$H,'Expenses Log'!$B:$B, $A8,'Expenses Log'!$M:$M, F$1) -> 0 | H8: 200 | I8: =sumifs('Expenses Log'!$H:$H,'Expenses Log'!$B:$B, $A8,'Expenses Log'!$M:$M, H$1) -> 0 | K8: =sumifs('Expenses Log'!$H:$H,'Expenses Log'!$B:$B, $A8,'Expenses Log'!$M:$M, J$1) -> 0 | L8: 200 | M8: =sumifs('Expenses Log'!$H:$H,'Expenses Log'!$B:$B, $A8,'Expenses Log'!$M:$M, L$1) -> 0 | O8: =sumifs('Expenses Log'!$H:$H,'Expenses Log'!$B:$B, $A8,'Expenses Log'!$M:$M, N$1) -> -40 | Q8: =sumifs('Expenses Log'!$H:$H,'Expenses Log'!$B:$B, $A8,'Expenses Log'!$M:$M, P$1) -> 0 | R8: 200 | S8: =sumifs('Expenses Log'!$H:$H,'Expenses Log'!$B:$B, $A8,'Expenses Log'!$M:$M, R$1) -> 0 | U8: =sumifs('Expenses Log'!$H:$H,'Expenses Log'!$B:$B, $A8,'Expenses Log'!$M:$M, T$1) -> 0 | W8: =sumifs('Expenses Log'!$H:$H,'Expenses Log'!$B:$B, $A8,'Expenses Log'!$M:$M, V$1) -> 0 | X8: =sum(B8,D8,F8,H8,J8,L8,N8,P8,R8,T8,V8) -> 800 | Y8: =sum(C8,E8,G8,I8,K8,M8,O8,Q8,S8,U8,W8) -> -40
A9: Monthly Masjid Event | B9: =SUM(B10:B11) -> 300 | C9: =SUM(C10:C11) -> 0 | D9: =SUM(D10:D11) -> 300 | E9: =SUM(E10:E11) -> 0 | F9: =SUM(F10:F11) -> 300 | G9: =SUM(G10:G11) -> 0 | H9: =SUM(H10:H11) -> 300 | I9: =SUM(I10:I11) -> 0 | ... Y9: =SUM(Y10:Y11) -> 763.81
A10: Youth Night | B10: 125 | C10: =sumifs('Expenses Log'!$H:$H,'Expenses Log'!$B:$B, $A10,'Expenses Log'!$M:$M, B$1) -> 0 | D10: 125 | E10: =sumifs('Expenses Log'!$H:$H,'Expenses Log'!$B:$B, $A10,'Expenses Log'!$M:$M, D$1) -> 0 | F10: 125 | G10: =sumifs('Expenses Log'!$H:$H,'Expenses Log'!$B:$B, $A10,'Expenses Log'!$M:$M, F$1) -> 0 | H10: 125 | I10: =sumifs('Expenses Log'!$H:$H,'Expenses Log'!$B:$B, $A10,'Expenses Log'!$M:$M, H$1) -> 0 | J10: 125 | K10: =sumifs('Expenses Log'!$H:$H,'Expenses Log'!$B:$B, $A10,'Expenses Log'!$M:$M, J$1) -> 363.81 | M10: =sumifs('Expenses Log'!$H:$H,'Expenses Log'!$B:$B, $A10,'Expenses Log'!$M:$M, L$1) -> 0 | N10: 125 | O10: =sumifs('Expenses Log'!$H:$H,'Expenses Log'!$B:$B, $A10,'Expenses Log'!$M:$M, N$1) -> 0 | P10: 125 | Q10: =sumifs('Expenses Log'!$H:$H,'Expenses Log'!$B:$B, $A10,'Expenses Log'!$M:$M, P$1) -> 0 | R10: 125 | S10: =sumifs('Expenses Log'!$H:$H,'Expenses Log'!$B:$B, $A10,'Expenses Log'!$M:$M, R$1) -> 0 | T10: 125 | U10: =sumifs('Expenses Log'!$H:$H,'Expenses Log'!$B:$B, $A10,'Expenses Log'!$M:$M, T$1) -> 0 | V10: 125 | W10: =sumifs('Expenses Log'!$H:$H,'Expenses Log'!$B:$B, $A10,'Expenses Log'!$M:$M, V$1) -> 0 | X10: =sum(B10,D10,F10,H10,J10,L10,N10,P10,R10,T10,V10) -> 1250 | Y10: =sum(C10,E10,G10,I10,K10,M10,O10,Q10,S10,U10,W10) -> 363.81
A11: Family Night | B11: 175 | C11: =sumifs('Expenses Log'!$H:$H,'Expenses Log'!$B:$B, $A11,'Expenses Log'!$M:$M, B$1) -> 0 | D11: 175 | E11: =sumifs('Expenses Log'!$H:$H,'Expenses Log'!$B:$B, $A11,'Expenses Log'!$M:$M, D$1) -> 0 | F11: 175 | G11: =sumifs('Expenses Log'!$H:$H,'Expenses Log'!$B:$B, $A11,'Expenses Log'!$M:$M, F$1) -> 0 | H11: 175 | I11: =sumifs('Expenses Log'!$H:$H,'Expenses Log'!$B:$B, $A11,'Expenses Log'!$M:$M, H$1) -> 0 | J11: 475 | K11: =sumifs('Expenses Log'!$H:$H,'Expenses Log'!$B:$B, $A11,'Expenses Log'!$M:$M, J$1) -> 400 | M11: =sumifs('Expenses Log'!$H:$H,'Expenses Log'!$B:$B, $A11,'Expenses Log'!$M:$M, L$1) -> 0 | N11: 175 | O11: =sumifs('Expenses Log'!$H:$H,'Expenses Log'!$B:$B, $A11,'Expenses Log'!$M:$M, N$1) -> 0 | P11: 475 | Q11: =sumifs('Expenses Log'!$H:$H,'Expenses Log'!$B:$B, $A11,'Expenses Log'!$M:$M, P$1) -> 0 | R11: 175 | S11: =sumifs('Expenses Log'!$H:$H,'Expenses Log'!$B:$B, $A11,'Expenses Log'!$M:$M, R$1) -> 0 | T11: 175 | U11: =sumifs('Expenses Log'!$H:$H,'Expenses Log'!$B:$B, $A11,'Expenses Log'!$M:$M, T$1) -> 0 | V11: 175 | W11: =sumifs('Expenses Log'!$H:$H,'Expenses Log'!$B:$B, $A11,'Expenses Log'!$M:$M, V$1) -> 0 | X11: =sum(B11,D11,F11,H11,J11,L11,N11,P11,R11,T11,V11) -> 2350 | Y11: =sum(C11,E11,G11,I11,K11,M11,O11,Q11,S11,U11,W11) -> 400
A12: Ramadan | B12: =SUM(B13:B18) -> 0 | C12: =SUM(C13:C18) -> 0 | D12: =SUM(D13:D18) -> 0 | E12: =SUM(E13:E18) -> 0 | F12: =SUM(F13:F18) -> 0 | G12: =SUM(G13:G18) -> 0 | H12: =SUM(H13:H18) -> 0 | I12: =SUM(I13:I18) -> 0 | ... Y12: =SUM(Y13:Y18) -> 3178.92
A13: Youth Girls Itikaaf | C13: =sumifs('Expenses Log'!$H:$H,'Expenses Log'!$B:$B, $A13,'Expenses Log'!$M:$M, B$1) -> 0 | E13: =sumifs('Expenses Log'!$H:$H,'Expenses Log'!$B:$B, $A13,'Expenses Log'!$M:$M, D$1) -> 0 | G13: =sumifs('Expenses Log'!$H:$H,'Expenses Log'!$B:$B, $A13,'Expenses Log'!$M:$M, F$1) -> 0 | I13: =sumifs('Expenses Log'!$H:$H,'Expenses Log'!$B:$B, $A13,'Expenses Log'!$M:$M, H$1) -> 0 | K13: =sumifs('Expenses Log'!$H:$H,'Expenses Log'!$B:$B, $A13,'Expenses Log'!$M:$M, J$1) -> 0 | L13: 0 | M13: =sumifs('Expenses Log'!$H:$H,'Expenses Log'!$B:$B, $A13,'Expenses Log'!$M:$M, L$1) -> 100.13 | O13: =sumifs('Expenses Log'!$H:$H,'Expenses Log'!$B:$B, $A13,'Expenses Log'!$M:$M, N$1) -> 0 | Q13: =sumifs('Expenses Log'!$H:$H,'Expenses Log'!$B:$B, $A13,'Expenses Log'!$M:$M, P$1) -> 0 | S13: =sumifs('Expenses Log'!$H:$H,'Expenses Log'!$B:$B, $A13,'Expenses Log'!$M:$M, R$1) -> 0 | U13: =sumifs('Expenses Log'!$H:$H,'Expenses Log'!$B:$B, $A13,'Expenses Log'!$M:$M, T$1) -> 0 | W13: =sumifs('Expenses Log'!$H:$H,'Expenses Log'!$B:$B, $A13,'Expenses Log'!$M:$M, V$1) -> 0 | X13: =sum(B13,D13,F13,H13,J13,L13,N13,P13,R13,T13,V13) -> 0 | Y13: =sum(C13,E13,G13,I13,K13,M13,O13,Q13,S13,U13,W13) -> 100.13
A14: Youth Boys Itikaaf | C14: =sumifs('Expenses Log'!$H:$H,'Expenses Log'!$B:$B, $A14,'Expenses Log'!$M:$M, B$1) -> 0 | E14: =sumifs('Expenses Log'!$H:$H,'Expenses Log'!$B:$B, $A14,'Expenses Log'!$M:$M, D$1) -> 0 | G14: =sumifs('Expenses Log'!$H:$H,'Expenses Log'!$B:$B, $A14,'Expenses Log'!$M:$M, F$1) -> 0 | I14: =sumifs('Expenses Log'!$H:$H,'Expenses Log'!$B:$B, $A14,'Expenses Log'!$M:$M, H$1) -> 0 | K14: =sumifs('Expenses Log'!$H:$H,'Expenses Log'!$B:$B, $A14,'Expenses Log'!$M:$M, J$1) -> 0 | L14: 800 | M14: =sumifs('Expenses Log'!$H:$H,'Expenses Log'!$B:$B, $A14,'Expenses Log'!$M:$M, L$1) -> 490.41 | O14: =sumifs('Expenses Log'!$H:$H,'Expenses Log'!$B:$B, $A14,'Expenses Log'!$M:$M, N$1) -> 0 | Q14: =sumifs('Expenses Log'!$H:$H,'Expenses Log'!$B:$B, $A14,'Expenses Log'!$M:$M, P$1) -> 0 | S14: =sumifs('Expenses Log'!$H:$H,'Expenses Log'!$B:$B, $A14,'Expenses Log'!$M:$M, R$1) -> 0 | U14: =sumifs('Expenses Log'!$H:$H,'Expenses Log'!$B:$B, $A14,'Expenses Log'!$M:$M, T$1) -> 0 | W14: =sumifs('Expenses Log'!$H:$H,'Expenses Log'!$B:$B, $A14,'Expenses Log'!$M:$M, V$1) -> 0 | X14: =sum(B14,D14,F14,H14,J14,L14,N14,P14,R14,T14,V14) -> 800 | Y14: =sum(C14,E14,G14,I14,K14,M14,O14,Q14,S14,U14,W14) -> 490.41
A15: Jr. Youth Girls Itikaaf | C15: =sumifs('Expenses Log'!$H:$H,'Expenses Log'!$B:$B, $A15,'Expenses Log'!$M:$M, B$1) -> 0 | E15: =sumifs('Expenses Log'!$H:$H,'Expenses Log'!$B:$B, $A15,'Expenses Log'!$M:$M, D$1) -> 0 | G15: =sumifs('Expenses Log'!$H:$H,'Expenses Log'!$B:$B, $A15,'Expenses Log'!$M:$M, F$1) -> 0 | I15: =sumifs('Expenses Log'!$H:$H,'Expenses Log'!$B:$B, $A15,'Expenses Log'!$M:$M, H$1) -> 0 | K15: =sumifs('Expenses Log'!$H:$H,'Expenses Log'!$B:$B, $A15,'Expenses Log'!$M:$M, J$1) -> 0 | L15: 0 | M15: =sumifs('Expenses Log'!$H:$H,'Expenses Log'!$B:$B, $A15,'Expenses Log'!$M:$M, L$1) -> 0 | O15: =sumifs('Expenses Log'!$H:$H,'Expenses Log'!$B:$B, $A15,'Expenses Log'!$M:$M, N$1) -> 0 | Q15: =sumifs('Expenses Log'!$H:$H,'Expenses Log'!$B:$B, $A15,'Expenses Log'!$M:$M, P$1) -> 0 | S15: =sumifs('Expenses Log'!$H:$H,'Expenses Log'!$B:$B, $A15,'Expenses Log'!$M:$M, R$1) -> 0 | U15: =sumifs('Expenses Log'!$H:$H,'Expenses Log'!$B:$B, $A15,'Expenses Log'!$M:$M, T$1) -> 0 | W15: =sumifs('Expenses Log'!$H:$H,'Expenses Log'!$B:$B, $A15,'Expenses Log'!$M:$M, V$1) -> 0 | X15: =sum(B15,D15,F15,H15,J15,L15,N15,P15,R15,T15,V15) -> 0 | Y15: =sum(C15,E15,G15,I15,K15,M15,O15,Q15,S15,U15,W15) -> 0
A16: Jr. Youth Boys Itikaaf | C16: =sumifs('Expenses Log'!$H:$H,'Expenses Log'!$B:$B, $A16,'Expenses Log'!$M:$M, B$1) -> 0 | E16: =sumifs('Expenses Log'!$H:$H,'Expenses Log'!$B:$B, $A16,'Expenses Log'!$M:$M, D$1) -> 0 | G16: =sumifs('Expenses Log'!$H:$H,'Expenses Log'!$B:$B, $A16,'Expenses Log'!$M:$M, F$1) -> 0 | I16: =sumifs('Expenses Log'!$H:$H,'Expenses Log'!$B:$B, $A16,'Expenses Log'!$M:$M, H$1) -> 0 | K16: =sumifs('Expenses Log'!$H:$H,'Expenses Log'!$B:$B, $A16,'Expenses Log'!$M:$M, J$1) -> 0 | L16: 500 | M16: =sumifs('Expenses Log'!$H:$H,'Expenses Log'!$B:$B, $A16,'Expenses Log'!$M:$M, L$1) -> 424.29 | O16: =sumifs('Expenses Log'!$H:$H,'Expenses Log'!$B:$B, $A16,'Expenses Log'!$M:$M, N$1) -> 0 | Q16: =sumifs('Expenses Log'!$H:$H,'Expenses Log'!$B:$B, $A16,'Expenses Log'!$M:$M, P$1) -> 0 | S16: =sumifs('Expenses Log'!$H:$H,'Expenses Log'!$B:$B, $A16,'Expenses Log'!$M:$M, R$1) -> 0 | U16: =sumifs('Expenses Log'!$H:$H,'Expenses Log'!$B:$B, $A16,'Expenses Log'!$M:$M, T$1) -> 0 | W16: =sumifs('Expenses Log'!$H:$H,'Expenses Log'!$B:$B, $A16,'Expenses Log'!$M:$M, V$1) -> 0 | X16: =sum(B16,D16,F16,H16,J16,L16,N16,P16,R16,T16,V16) -> 500 | Y16: =sum(C16,E16,G16,I16,K16,M16,O16,Q16,S16,U16,W16) -> 424.29
A17: Quran Competition | C17: =sumifs('Expenses Log'!$H:$H,'Expenses Log'!$B:$B, $A17,'Expenses Log'!$M:$M, B$1) -> 0 | E17: =sumifs('Expenses Log'!$H:$H,'Expenses Log'!$B:$B, $A17,'Expenses Log'!$M:$M, D$1) -> 0 | G17: =sumifs('Expenses Log'!$H:$H,'Expenses Log'!$B:$B, $A17,'Expenses Log'!$M:$M, F$1) -> 0 | I17: =sumifs('Expenses Log'!$H:$H,'Expenses Log'!$B:$B, $A17,'Expenses Log'!$M:$M, H$1) -> 0 | K17: =sumifs('Expenses Log'!$H:$H,'Expenses Log'!$B:$B, $A17,'Expenses Log'!$M:$M, J$1) -> 0 | L17: 1000 | M17: =sumifs('Expenses Log'!$H:$H,'Expenses Log'!$B:$B, $A17,'Expenses Log'!$M:$M, L$1) -> 1071.7 | O17: =sumifs('Expenses Log'!$H:$H,'Expenses Log'!$B:$B, $A17,'Expenses Log'!$M:$M, N$1) -> 0 | Q17: =sumifs('Expenses Log'!$H:$H,'Expenses Log'!$B:$B, $A17,'Expenses Log'!$M:$M, P$1) -> 0 | S17: =sumifs('Expenses Log'!$H:$H,'Expenses Log'!$B:$B, $A17,'Expenses Log'!$M:$M, R$1) -> 0 | U17: =sumifs('Expenses Log'!$H:$H,'Expenses Log'!$B:$B, $A17,'Expenses Log'!$M:$M, T$1) -> 0 | W17: =sumifs('Expenses Log'!$H:$H,'Expenses Log'!$B:$B, $A17,'Expenses Log'!$M:$M, V$1) -> 0 | X17: =sum(B17,D17,F17,H17,J17,L17,N17,P17,R17,T17,V17) -> 1000 | Y17: =sum(C17,E17,G17,I17,K17,M17,O17,Q17,S17,U17,W17) -> 1071.7
A18: Youth Eid Festival | C18: =sumifs('Expenses Log'!$H:$H,'Expenses Log'!$B:$B, $A18,'Expenses Log'!$M:$M, B$1) -> 0 | E18: =sumifs('Expenses Log'!$H:$H,'Expenses Log'!$B:$B, $A18,'Expenses Log'!$M:$M, D$1) -> 0 | G18: =sumifs('Expenses Log'!$H:$H,'Expenses Log'!$B:$B, $A18,'Expenses Log'!$M:$M, F$1) -> 0 | I18: =sumifs('Expenses Log'!$H:$H,'Expenses Log'!$B:$B, $A18,'Expenses Log'!$M:$M, H$1) -> 0 | K18: =sumifs('Expenses Log'!$H:$H,'Expenses Log'!$B:$B, $A18,'Expenses Log'!$M:$M, J$1) -> 0 | L18: 1000 | M18: =sumifs('Expenses Log'!$H:$H,'Expenses Log'!$B:$B, $A18,'Expenses Log'!$M:$M, L$1) -> 1092.39 | O18: =sumifs('Expenses Log'!$H:$H,'Expenses Log'!$B:$B, $A18,'Expenses Log'!$M:$M, N$1) -> 0 | Q18: =sumifs('Expenses Log'!$H:$H,'Expenses Log'!$B:$B, $A18,'Expenses Log'!$M:$M, P$1) -> 0 | S18: =sumifs('Expenses Log'!$H:$H,'Expenses Log'!$B:$B, $A18,'Expenses Log'!$M:$M, R$1) -> 0 | U18: =sumifs('Expenses Log'!$H:$H,'Expenses Log'!$B:$B, $A18,'Expenses Log'!$M:$M, T$1) -> 0 | W18: =sumifs('Expenses Log'!$H:$H,'Expenses Log'!$B:$B, $A18,'Expenses Log'!$M:$M, V$1) -> 0 | X18: =sum(B18,D18,F18,H18,J18,L18,N18,P18,R18,T18,V18) -> 1000 | Y18: =sum(C18,E18,G18,I18,K18,M18,O18,Q18,S18,U18,W18) -> 1092.39
A19: Special Events | B19: =SUM(B20:B21) -> 0 | C19: =SUM(C20:C21) -> 3000 | D19: =SUM(D20:D21) -> 0 | E19: =SUM(E20:E21) -> 0 | F19: =SUM(F20:F21) -> 0 | G19: =SUM(G20:G21) -> 0 | H19: =SUM(H20:H21) -> 0 | I19: =SUM(I20:I21) -> 0 | ... W19: =SUM(W20:W21) -> 0 | X19: =sum(X20,X21) -> 2500 | Y19: =sum(Y20,Y21) -> 3000
A20: Family BBQ | C20: =sumifs('Expenses Log'!$H:$H,'Expenses Log'!$B:$B, $A20,'Expenses Log'!$M:$M, B$1) -> 0 | E20: =sumifs('Expenses Log'!$H:$H,'Expenses Log'!$B:$B, $A20,'Expenses Log'!$M:$M, D$1) -> 0 | G20: =sumifs('Expenses Log'!$H:$H,'Expenses Log'!$B:$B, $A20,'Expenses Log'!$M:$M, F$1) -> 0 | I20: =sumifs('Expenses Log'!$H:$H,'Expenses Log'!$B:$B, $A20,'Expenses Log'!$M:$M, H$1) -> 0 | K20: =sumifs('Expenses Log'!$H:$H,'Expenses Log'!$B:$B, $A20,'Expenses Log'!$M:$M, J$1) -> 0 | M20: =sumifs('Expenses Log'!$H:$H,'Expenses Log'!$B:$B, $A20,'Expenses Log'!$M:$M, L$1) -> 0 | O20: =sumifs('Expenses Log'!$H:$H,'Expenses Log'!$B:$B, $A20,'Expenses Log'!$M:$M, N$1) -> 0 | Q20: =sumifs('Expenses Log'!$H:$H,'Expenses Log'!$B:$B, $A20,'Expenses Log'!$M:$M, P$1) -> 0 | R20: 2500 | S20: =sumifs('Expenses Log'!$H:$H,'Expenses Log'!$B:$B, $A20,'Expenses Log'!$M:$M, R$1) -> 0 | U20: =sumifs('Expenses Log'!$H:$H,'Expenses Log'!$B:$B, $A20,'Expenses Log'!$M:$M, T$1) -> 0 | W20: =sumifs('Expenses Log'!$H:$H,'Expenses Log'!$B:$B, $A20,'Expenses Log'!$M:$M, V$1) -> 0 | X20: =sum(B20,D20,F20,H20,J20,L20,N20,P20,R20,T20,V20) -> 2500 | Y20: =sum(C20,E20,G20,I20,K20,M20,O20,Q20,S20,U20,W20) -> 0
A21: Ibn Katheer Quran Competition | C21: 3000 | X21: =sum(B21,D21,F21,H21,J21,L21,N21,P21,R21,T21,V21) -> 0 | Y21: =sum(C21,E21,G21,I21,K21,M21,O21,Q21,S21,U21,W21) -> 3000
A22: TOTALS | B22: =sum(B3,B6,B9,B12,B19) -> 815 | C22: =sum(C3,C6,C9,C12,C19) -> 3000 | D22: =sum(D3,D6,D9,D12,D19) -> 335 | E22: =sum(E3,E6,E9,E12,E19) -> 0 | F22: =sum(F3,F6,F9,F12,F19) -> 335 | G22: =sum(G3,G6,G9,G12,G19) -> 0 | H22: =sum(H3,H6,H9,H12,H19) -> 535 | I22: =sum(I3,I6,I9,I12,I19) -> 0 | ... Y22: =sum(Y3,Y6,Y9,Y12,Y19) -> 10236.9

Sheet Expenses Log
A1: Date | B1: Budget Group | C1: Expense Type | D1: Vendor | E1: Description | F1: Sub-Total | G1: Adjustments | H1: Total | I1: Paid By | J1: Status | K1: Receipt | L1: Notes | M1: Budget Month
A2: 46003 | B2: Youth Night | C2: Food & Drink | D2: Costco | E2: Juice and Mandarins | F2: =3.99+13.89 -> 17.88 | G2: 17.88 | H2: =F2-G2 -> 0 | I2: Umair | J2: Donation | M2: December
A3: 46003 | B3: Youth Night | C3: Supplies | D3: Costco | E3: Boys Award | F3: 22.99 | G3: 22.99 | H3: =F3-G3 -> 0 | I3: Umair | J3: Donation | M3: December
A4: 46003 | B4: Youth Night | C4: Food & Drink | D4: Costco | E4: 14 Cheese Pizza | F4: 139.3 | G4: 139.3 | H4: =F4-G4 -> 0 | I4: Umair | J4: Donation | M4: December
A5: 46023 | B5: Guest Speaker | C5: Lodging | D5: Staybridge Suites Hillsboro North | E5: Sh. Asim Hotel | F5: 460.31 | G5: 153.43 | H5: =F5-G5 -> 306.88 | I5: Sh. Asim | J5: Paid | K5: 2026-01-01_StaybridgeSuites_ShAsimHotel.pdf | L5: ICCH paid for one night of stay since they are using him as a guest speaker at their Friday night event. | M5: January
A6: 46029 | B6: Guest Speaker | C6: Transportation | D6: Alaska Airlines | E6: Sh. Asim Flights | F6: 244.29 | G6: 0 | H6: =F6-G6 -> 244.29 | I6: Sh. Asim | J6: Paid | K6: 2026-01-07_AlaskaAirlines_ShAsimFlight.pdf | M6: January
A7: 46035 | B7: Youth Night | C7: Food & Drink | D7: Yasmeen Cafe | E7: Coffee Bar | F7: 125 | G7: 0 | H7: =F7-G7 -> 125 | I7: Umair | J7: Paid | K7: 2026-01-13_YasmeenCafe_CoffeeBar.pdf | M7: January
A8: 46038 | B8: Youth Night | C8: Venue | D8: US Chef Store | E8: Event Supplies | F8: 21.16 | G8: 0 | H8: =F8-G8 -> 21.16 | I8: Fatmah | J8: Paid | K8: 2026-01-16_USChefStore_Supplies.jpeg | M8: January
A9: 46039 | B9: Youth Night | C9: Food & Drink | D9: Costco | E9: Pizza | F9: 69.65 | G9: 0 | H9: =F9-G9 -> 69.65 | I9: Umair | J9: Paid | K9: 2026-01-20_Costco_Pizza.png | M9: January
A10: 46039 | B10: Youth Night | C10: Food & Drink | D10: Sugary Kneads | E10: 2 Dozen Pastries | F10: 120 | G10: 0 | H10: =F10-G10 -> 120 | I10: Umair | J10: Paid | K10: 2026-01-17_SugaryKneads_2DozenPastries.pdf | M10: January
A11: 46039 | B11: Youth Night | C11: Food & Drink | D11: Yasmeen Cafe | E11: Coffee Bar (2) | F11: 28 | G11: 0 | H11: =F11-G11 -> 28 | I11: Umair | J11: Paid | K11: 2026-01-17_YasmeenCafe_CoffeeBar.pdf | M11: January
A12: 46039 | B12: Family Night | C12: Food & Drink | D12: Adhil Bhai | E12: Chicken Over Rice | F12: 400 | G12: 0 | H12: =F12-G12 -> 400 | I12: Adhil Bhai | J12: Paid | L12: No receipt available | M12: January
A13: 46039 | B13: Guest Speaker | C13: Honorarium/Services | D13: Muslim Gift Box | E13: Sh. Asim Gift Box | F13: 40 | G13: 0 | H13: =F13-G13 -> 40 | I13: Hina Aunty | J13: Paid | K13: 2026-01-17_MuslimGiftBox_ShAsimGiftBox.jpeg | M13: January
A14: 46040 | B14: Guest Speaker | C14: Transportation | D14: Alaska Airlines | E14: Sh. Asim Check In | F14: 40 | G14: 0 | H14: =F14-G14 -> 40 | I14: Sh. Asim | J14: Paid | K14: 2026-01-18_AlaskaAirlines_ShAsimCheckIn.pdf | M14: January
A15: 46043 | B15: Guest Speaker | C15: Honorarium/Services | D15: Sh. Asim Billoo | E15: Honorarium | F15: 1000 | G15: 0 | H15: =F15-G15 -> 1000 | I15: Bilal Masjid | J15: Direct | M15: January
A16: 46051 | B16: Tech | C16: Tech | D16: Tally | E16: Annual Plan | F16: 203 | G16: 0 | H16: =F16-G16 -> 203 | I16: Umair | J16: Paid | M16: January
A17: 46075 | B17: Youth Boys Itikaaf | C17: Supplies | D17: Amazon | E17: Boys Lanyards | F17: 29.99 | G17: 0 | H17: =F17-G17 -> 29.99 | I17: Umair | J17: Paid | K17: 2026-02-22_Amazon_Lanyards.pdf | M17: Ramadan
A18: 46075 | B18: Youth Boys Itikaaf | C18: Supplies | D18: Amazon | E18: Boys Badge Holders | F18: 24.99 | G18: 0 | H18: =F18-G18 -> 24.99 | I18: Umair | J18: Paid | K18: 2026-02-22_Amazon_BadgeHolders.pdf | M18: Ramadan
A19: 46075 | B19: Youth Girls Itikaaf | C19: Supplies | D19: Amazon | E19: Girls Lanyards, Badge Holders | F19: 54.98 | G19: 0 | H19: =F19-G19 -> 54.98 | I19: Umair | J19: Paid | K19: 2026-02-22_Amazon_GirlsBadges.pdf | M19: Ramadan
A20: 46077 | B20: Jr. Youth Boys Itikaaf | C20: Supplies | D20: Amazon | E20: Markers | F20: 29.99 | G20: 0 | H20: =F20-G20 -> 29.99 | I20: Umair | J20: Paid | K20: 2026-02-24_Amazon_Markers.pdf | M20: Ramadan
A21: 46077 | B21: Jr. Youth Boys Itikaaf | C21: Supplies | D21: Amazon | E21: Paper Roll | F21: 8.98 | G21: 0 | H21: =F21-G21 -> 8.98 | I21: Umair | J21: Paid | K21: 2026-02-24_Amazon_PaperRoll.pdf | M21: Ramadan
A22: 46077 | B22: Jr. Youth Boys Itikaaf | C22: Supplies | D22: Amazon | E22: Stencils | F22: 17.76 | G22: 0 | H22: =F22-G22 -> 17.76 | I22: Umair | J22: Paid | K22: 2026-02-24_Amazon_Stencils.pdf | M22: Ramadan
A23: 46077 | B23: Jr. Youth Boys Itikaaf | C23: Supplies | D23: MarkySparkyToys | E23: Activities for Mini Itikaaf | F23: 150 | G23: 0 | H23: =F23-G23 -> 150 | I23: Umair | J23: Paid | K23: 2026-02-24_MarkySparky_BowKit.pdf | M23: Ramadan
A24: 46078 | B24: Youth Boys Itikaaf | C24: Supplies | D24: Etsy | E24: Awards Boys Itikaaf | F24: 92.8 | G24: 0 | H24: =F24-G24 -> 92.8 | I24: Umair | J24: Paid | K24: 2026-02-25_Etsy_YouthBookmarks | M24: Ramadan
A25: 46079 | B25: Jr. Youth Boys Itikaaf | C25: Supplies | D25: Amazon | E25: Stickers | F25: 9.99 | G25: 0 | H25: =F25-G25 -> 9.99 | I25: Umair | J25: Paid | K25: 2026-02-26_Amazon_Stickers.pdf | M25: Ramadan
A26: 46081 | B26: Youth Girls Itikaaf | C26: Supplies | D26: FedEx | E26: Badges Print & Cut | F26: =90.3/2 -> 45.15 | G26: 0 | H26: =F26-G26 -> 45.15 | I26: Umair | J26: Paid | K26: 2026-02-28_FedEx_BadgePrint&Cut | M26: Ramadan
A27: 46081 | B27: Jr. Youth Boys Itikaaf | C27: Supplies | D27: FedEx | E27: Badges Print & Cut | F27: =90.3/2 -> 45.15 | G27: 0 | H27: =F27-G27 -> 45.15 | I27: Umair | J27: Paid | K27: 2026-02-28_FedEx_BadgePrint&Cut | M27: Ramadan
A28: 46081 | B28: Jr. Youth Boys Itikaaf | C28: Supplies | D28: Target | E28: Prizes Mini Itikaaf | F28: 112.42 | G28: 0 | H28: =F28-G28 -> 112.42 | I28: Tajwar | J28: Paid | K28: 2026-02-28_Target_Prizes | M28: Ramadan
A29: 46081 | B29: Jr. Youth Boys Itikaaf | C29: Food & Drink | D29: Costco | E29: 5x Pizza | F29: 50 | G29: 0 | H29: =F29-G29 -> 50 | I29: Umair | J29: Paid | K29: 2026-03-01_Costco_Pizza.pdf | M29: Ramadan
A30: 46088 | B30: Youth Boys Itikaaf | C30: Food & Drink | D30: Dave's Hot Chicken | E30: Sandwiches | F30: 260 | G30: 0 | H30: =F30-G30 -> 260 | I30: Umair | J30: Paid | K30: 2026-03-07_DavesHotChicken_Burgers.pdf | M30: Ramadan
A31: 46088 | B31: Youth Boys Itikaaf | C31: Supplies | D31: FedEx | E31: Badges Print & Cut | F31: 75.13 | G31: 0 | H31: =F31-G31 -> 75.13 | I31: Umair | J31: Paid | K31: 2026-03-07_FedEx_BadgesPrint&Cut.PNG | M31: Ramadan
A32: 46092 | B32: Quran Competition | C32: Supplies | D32: Amazon | E32: Quran Contest Lanyards | F32: 15.98 | G32: 0 | H32: =F32-G32 -> 15.98 | I32: Umair | J32: Paid | K32: 2026-03-11_Amazon_Lanyards.pdf | M32: Ramadan
A33: 46093 | B33: Youth Boys Itikaaf | C33: Supplies | D33: Dollar Tree | E33: Table Covers | F33: 7.5 | G33: 0 | H33: =F33-G33 -> 7.5 | I33: Umair | J33: Paid | K33: 2026-03-12_DollarTree_TableCovers.pdf | M33: Ramadan
A34: 46094 | B34: Quran Competition | C34: Supplies | D34: Amazon | E34: Quran Contest Badge Holders | F34: 27.98 | G34: 0 | H34: =F34-G34 -> 27.98 | I34: Umair | J34: Paid | K34: 2026-03-13_Amazon_BadgeHolders.pdf | M34: Ramadan
A35: 46095 | B35: Quran Competition | C35: Supplies | D35: Costco | E35: Good Bags | F35: 127.74 | G35: 0 | H35: =F35-G35 -> 127.74 | I35: Hina Aunty | J35: Paid | L35: No receipt available | M35: Ramadan
A36: 46095 | B36: Quran Competition | C36: Supplies | E36: Certificates | F36: 75 | G36: 0 | H36: =F36-G36 -> 75 | I36: Hina Aunty | J36: Paid | L36: No receipt available | M36: Ramadan
A37: 46095 | B37: Quran Competition | C37: Supplies | D37: Bank | E37: Cash Prizes | F37: 825 | G37: 0 | H37: =F37-G37 -> 825 | I37: Hina Aunty | J37: Paid | L37: No receipt available | M37: Ramadan
A38: 46104 | B38: Youth Eid Festival | C38: Supplies | D38: Amazon | E38: 30 Days 30 Deeds Prizes (1) | F38: 94.55 | G38: 0 | H38: =F38-G38 -> 94.55 | I38: Umair | J38: Paid | K38: 2026-03-23_Amazon_EidGifts.pdf | M38: Ramadan
A39: 46104 | B39: Youth Eid Festival | C39: Supplies | D39: Amazon | E39: 30 Days 30 Deeds Prizes (2) | F39: 16.99 | G39: 0 | H39: =F39-G39 -> 16.99 | I39: Umair | J39: Paid | K39: 2026-03-23_Amazon_EidGifts2.pdf | M39: Ramadan
A40: 46104 | B40: Youth Eid Festival | C40: Supplies | D40: Amazon | E40: Soccer Ball | F40: 9.99 | G40: 0 | H40: =F40-G40 -> 9.99 | I40: Umair | J40: Paid | K40: 2026-03-23_Amazon_SoccerBall.pdf | M40: Ramadan
...
